Workbook
Name Balcheck: 'MODEL&SCHEDULE'!$D$234
Name Base_Year: 'HISTORICAL FS'!$I$5
Name circularity: COVER!$C$21
Name Forecast_year: ASSUMPTIONS!$D$22
Name L_Scenarios: SCENARIOS!$C$15:$C$17
Name S_Scenario: SCENARIOS!$D$8

Sheet COVER
B6: NEXT PLC | F6: 3 STATEMENT FINANCIAL MODEL
E8: -
G10: Equity Research | Initiating Coverage
H11: ="FINANCIAL MODEL FOR " &Base_Year +1& " to " & Forecast_year+Base_Year -> FINANCIAL MODEL FOR 2027 to 2031
B15: Analyst : | C15: Oyindamola Aribilola
B17: Date : | C17: 46167
B19: Version : | C19: Ver 1.0
B21: Circularity Switch : | C21: 2
A30: Aim : | B30: To examine the firm's financial projections along with its competitors to determine if it is a SMART investment or not

Sheet SUMMARY
C1: KPI | K1: =SCENARIOS!K1 -> CURRENTLY RUNNING: BULL / BEST CASE
M2: ='HISTORICAL FS'!L2 -> NEXT PLC
M3: ='HISTORICAL FS'!L3 -> Bal Check: OK
G4: =ASSUMPTIONS!G4 -> 45322 | H4: =ASSUMPTIONS!H4 -> 45688 | I4: =ASSUMPTIONS!I4 -> 46053 | J4: =ASSUMPTIONS!J4 -> 46418 | K4: =ASSUMPTIONS!K4 -> 46783 | L4: =ASSUMPTIONS!L4 -> 47149 | M4: =ASSUMPTIONS!M4 -> 47514 | N4: =ASSUMPTIONS!N4 -> 47879
G5: =ASSUMPTIONS!G5 -> 2024 | H5: =ASSUMPTIONS!H5 -> 2025 | I5: =ASSUMPTIONS!I5 -> 2026 | J5: =ASSUMPTIONS!J5 -> 2027 | K5: =ASSUMPTIONS!K5 -> 2028 | L5: =ASSUMPTIONS!L5 -> 2029 | M5: =ASSUMPTIONS!M5 -> 2030 | N5: =ASSUMPTIONS!N5 -> 2031
D6: Units | E6: Trend
B7: Revenue
C8: ='MODEL&SCHEDULE'!C17 -> Revenue | D8: $MM | G8: ='MODEL&SCHEDULE'!G17 -> 5491 | H8: ='MODEL&SCHEDULE'!H17 -> 6118.1 | I8: ='MODEL&SCHEDULE'!I17 -> 6901.3 | J8: ='MODEL&SCHEDULE'!J17 -> 7275.704 | K8: ='MODEL&SCHEDULE'!K17 -> 7952.2216 | L8: ='MODEL&SCHEDULE'!L17 -> 8824.7422 | M8: ='MODEL&SCHEDULE'!M17 -> 9622.7977 | N8: ='MODEL&SCHEDULE'!N17 -> 10418.633
C9: Revenue Growth | D9: % | H9: =IFERROR(H8/G8-1,0) -> 0.11420506 | I9: =IFERROR(I8/H8-1,0) -> 0.1280136 | J9: =IFERROR(J8/I8-1,0) -> 0.054251228 | K9: =IFERROR(K8/J8-1,0) -> 0.092983118 | L9: =IFERROR(L8/K8-1,0) -> 0.10972036 | M9: =IFERROR(M8/L8-1,0) -> 0.090433853 | N9: =IFERROR(N8/M8-1,0) -> 0.082703069
B12: EBITDA
C13: ='MODEL&SCHEDULE'!C67 -> EBITDA | D13: $MM | G13: ='MODEL&SCHEDULE'!G67 -> 1211.1 | H13: ='MODEL&SCHEDULE'!H67 -> 1363.9 | I13: ='MODEL&SCHEDULE'!I67 -> 1574.5 | J13: ='MODEL&SCHEDULE'!J67 -> 1688.1824 | K13: ='MODEL&SCHEDULE'!K67 -> 1835.0381 | L13: ='MODEL&SCHEDULE'!L67 -> 2017.8368 | M13: ='MODEL&SCHEDULE'!M67 -> 2186.1258 | N13: ='MODEL&SCHEDULE'!N67 -> 2353.4501
C14: EBITDA Growth | D14: % | H14: =IFERROR(H13/G13-1,0) -> 0.1261663 | I14: =IFERROR(I13/H13-1,0) -> 0.15441015 | J14: =IFERROR(J13/I13-1,0) -> 0.072202198 | K14: =IFERROR(K13/J13-1,0) -> 0.086990474 | L14: =IFERROR(L13/K13-1,0) -> 0.099615734 | M14: =IFERROR(M13/L13-1,0) -> 0.083400708 | N14: =IFERROR(N13/M13-1,0) -> 0.07653919
C15: ='MODEL&SCHEDULE'!C78 -> EBITDA margin | D15: % | G15: ='MODEL&SCHEDULE'!G78 -> 0.22056092 | H15: ='MODEL&SCHEDULE'!H78 -> 0.22292869 | I15: ='MODEL&SCHEDULE'!I78 -> 0.22814542 | J15: ='MODEL&SCHEDULE'!J78 -> 0.2320301 | K15: ='MODEL&SCHEDULE'!K78 -> 0.23075792 | L15: ='MODEL&SCHEDULE'!L78 -> 0.22865674 | M15: ='MODEL&SCHEDULE'!M78 -> 0.22718194 | N15: ='MODEL&SCHEDULE'!N78 -> 0.22588858
B18: EBIT
C19: ='MODEL&SCHEDULE'!C64 -> EBIT | D19: $MM | G19: ='MODEL&SCHEDULE'!G64 -> 970.5 | H19: ='MODEL&SCHEDULE'!H64 -> 1075 | I19: ='MODEL&SCHEDULE'!I64 -> 1272 | J19: ='MODEL&SCHEDULE'!J64 -> 1380.5705 | K19: ='MODEL&SCHEDULE'!K64 -> 1509.3565 | L19: ='MODEL&SCHEDULE'!L64 -> 1675.3355 | M19: ='MODEL&SCHEDULE'!M64 -> 1827.4274 | N19: ='MODEL&SCHEDULE'!N64 -> 1979.3134
C20: EBIT Growth | D20: % | H20: =IFERROR(H19/G19-1,0) -> 0.10767646 | I20: =IFERROR(I19/H19-1,0) -> 0.18325581 | J20: =IFERROR(J19/I19-1,0) -> 0.085354152 | K20: =IFERROR(K19/J19-1,0) -> 0.093284673 | L20: =IFERROR(L19/K19-1,0) -> 0.10996672 | M20: =IFERROR(M19/L19-1,0) -> 0.090782958 | N20: =IFERROR(N19/M19-1,0) -> 0.083114624
C21: ='MODEL&SCHEDULE'!C77 -> EBIT margin | D21: % | G21: ='MODEL&SCHEDULE'!G77 -> 0.17674376 | H21: ='MODEL&SCHEDULE'!H77 -> 0.17570814 | I21: ='MODEL&SCHEDULE'!I77 -> 0.1843131 | J21: ='MODEL&SCHEDULE'!J77 -> 0.18975078 | K21: ='MODEL&SCHEDULE'!K77 -> 0.18980313 | L21: ='MODEL&SCHEDULE'!L77 -> 0.18984527 | M21: ='MODEL&SCHEDULE'!M77 -> 0.18990605 | N21: ='MODEL&SCHEDULE'!N77 -> 0.18997823
B24: EBIAT
C25: ='MODEL&SCHEDULE'!C73 -> EBIAT/NOPAT | D25: $MM | G25: ='MODEL&SCHEDULE'!G73 -> 727.875 | H25: ='MODEL&SCHEDULE'!H73 -> 806.25 | I25: ='MODEL&SCHEDULE'!I73 -> 954 | J25: ='MODEL&SCHEDULE'!J73 -> 1035.4279 | K25: ='MODEL&SCHEDULE'!K73 -> 1132.0174 | L25: ='MODEL&SCHEDULE'!L73 -> 1256.5016 | M25: ='MODEL&SCHEDULE'!M73 -> 1370.5706 | N25: ='MODEL&SCHEDULE'!N73 -> 1484.485
C26: EBIAT Growth | D26: % | H26: =IFERROR(H25/G25-1,0) -> 0.10767646 | I26: =IFERROR(I25/H25-1,0) -> 0.18325581 | J26: =IFERROR(J25/I25-1,0) -> 0.085354152 | K26: =IFERROR(K25/J25-1,0) -> 0.093284673 | L26: =IFERROR(L25/K25-1,0) -> 0.10996672 | M26: =IFERROR(M25/L25-1,0) -> 0.090782958 | N26: =IFERROR(N25/M25-1,0) -> 0.083114624
C27: ='MODEL&SCHEDULE'!C79 -> EBIAT/NOPAT margin | D27: % | G27: ='MODEL&SCHEDULE'!G79 -> 0.13255782 | H27: ='MODEL&SCHEDULE'!H79 -> 0.13178111 | I27: ='MODEL&SCHEDULE'!I79 -> 0.13823483 | J27: ='MODEL&SCHEDULE'!J79 -> 0.14231308 | K27: ='MODEL&SCHEDULE'!K79 -> 0.14235235 | L27: ='MODEL&SCHEDULE'!L79 -> 0.14238395 | M27: ='MODEL&SCHEDULE'!M79 -> 0.14242953 | N27: ='MODEL&SCHEDULE'!N79 -> 0.14248367
B31: Net Income
C32: ='MODEL&SCHEDULE'!C71 -> Recurring Net Income | D32: $MM | G32: ='MODEL&SCHEDULE'!G71 -> 868.9 | H32: ='MODEL&SCHEDULE'!H71 -> 742.9 | I32: ='MODEL&SCHEDULE'!I71 -> 892.9 | J32: ='MODEL&SCHEDULE'!J71 -> 1052.7284 | K32: ='MODEL&SCHEDULE'!K71 -> 1150.7809 | L32: ='MODEL&SCHEDULE'!L71 -> 1284.0156 | M32: ='MODEL&SCHEDULE'!M71 -> 1399.7976 | N32: ='MODEL&SCHEDULE'!N71 -> 1520.7002
C33: Net Income Growth | D33: % | H33: =IFERROR(H32/G32-1,0) -> -0.14501093 | I33: =IFERROR(I32/H32-1,0) -> 0.20191143 | J33: =IFERROR(J32/I32-1,0) -> 0.17899926 | K33: =IFERROR(K32/J32-1,0) -> 0.093141285 | L33: =IFERROR(L32/K32-1,0) -> 0.11577763 | M33: =IFERROR(M32/L32-1,0) -> 0.090171822 | N33: =IFERROR(N32/M32-1,0) -> 0.086371449
C34: ='MODEL&SCHEDULE'!C84 -> Recurring NI margin | D34: % | H34: ='MODEL&SCHEDULE'!H84 -> 0.12142659 | I34: ='MODEL&SCHEDULE'!I84 -> 0.12938142 | J34: ='MODEL&SCHEDULE'!J84 -> 0.14469094 | K34: ='MODEL&SCHEDULE'!K84 -> 0.14471188 | L34: ='MODEL&SCHEDULE'!L84 -> 0.14550177 | M34: ='MODEL&SCHEDULE'!M84 -> 0.14546681 | N34: ='MODEL&SCHEDULE'!N84 -> 0.14595967
B37: Dupont Analysis
C38: ='MODEL&SCHEDULE'!C87 -> Return on Equity | D38: ='MODEL&SCHEDULE'!D87 -> % | H38: ='MODEL&SCHEDULE'!H87 -> 0.43788866 | I38: ='MODEL&SCHEDULE'!I87 -> 0.50520539 | J38: ='MODEL&SCHEDULE'!J87 -> 0.54067219 | K38: ='MODEL&SCHEDULE'!K87 -> 0.50579958 | L38: ='MODEL&SCHEDULE'!L87 -> 0.47686312 | M38: ='MODEL&SCHEDULE'!M87 -> 0.43835069 | N38: ='MODEL&SCHEDULE'!N87 -> 0.40841995
C39: ='MODEL&SCHEDULE'!C84 -> Recurring NI margin | D39: ='MODEL&SCHEDULE'!D84 -> % | H39: ='MODEL&SCHEDULE'!H84 -> 0.12142659 | I39: ='MODEL&SCHEDULE'!I84 -> 0.12938142 | J39: ='MODEL&SCHEDULE'!J84 -> 0.14469094 | K39: ='MODEL&SCHEDULE'!K84 -> 0.14471188 | L39: ='MODEL&SCHEDULE'!L84 -> 0.14550177 | M39: ='MODEL&SCHEDULE'!M84 -> 0.14546681 | N39: ='MODEL&SCHEDULE'!N84 -> 0.14595967
C40: ='MODEL&SCHEDULE'!C85 -> Asset Turnover | D40: ='MODEL&SCHEDULE'!D85 -> Multiple | H40: ='MODEL&SCHEDULE'!H85 -> 1.2750292 | I40: ='MODEL&SCHEDULE'!I85 -> 1.4101841 | J40: ='MODEL&SCHEDULE'!J85 -> 1.4492829 | K40: ='MODEL&SCHEDULE'!K85 -> 1.4881154 | L40: ='MODEL&SCHEDULE'!L85 -> 1.5294244 | M40: ='MODEL&SCHEDULE'!M85 -> 1.5139156 | N40: ='MODEL&SCHEDULE'!N85 -> 1.4711132
C41: ='MODEL&SCHEDULE'!C86 -> Financial leverage | D41: ='MODEL&SCHEDULE'!D86 -> Multiple | H41: ='MODEL&SCHEDULE'!H86 -> 2.8283281 | I41: ='MODEL&SCHEDULE'!I86 -> 2.7689827 | J41: ='MODEL&SCHEDULE'!J86 -> 2.5783361 | K41: ='MODEL&SCHEDULE'!K86 -> 2.3487548 | L41: ='MODEL&SCHEDULE'!L86 -> 2.142878 | M41: ='MODEL&SCHEDULE'!M86 -> 1.9904722 | N41: ='MODEL&SCHEDULE'!N86 -> 1.9020765
C43: ='MODEL&SCHEDULE'!C81 -> Return on Asset | D43: ='MODEL&SCHEDULE'!D81 -> % | H43: ='MODEL&SCHEDULE'!H81 -> 0.15482244 | I43: ='MODEL&SCHEDULE'!I81 -> 0.18245162 | J43: ='MODEL&SCHEDULE'!J81 -> 0.20969811 | K43: ='MODEL&SCHEDULE'!K81 -> 0.21534797 | L43: ='MODEL&SCHEDULE'!L81 -> 0.22253395 | M43: ='MODEL&SCHEDULE'!M81 -> 0.22022447 | N43: ='MODEL&SCHEDULE'!N81 -> 0.2147232

Sheet HISTORICAL FS
C1: ANNUAL REPORT | K1: =SCENARIOS!K1 -> CURRENTLY RUNNING: BULL / BEST CASE
L2: =COVER!B6 -> NEXT PLC
L3: ='MODEL&SCHEDULE'!M3 -> Bal Check: OK
E4: =DATE(YEAR(F4)-1,MONTH(F4),DAY(F4)) -> 44592 | F4: =DATE(YEAR(G4)-1,MONTH(G4),DAY(G4)) -> 44957 | G4: =DATE(YEAR(H4)-1,MONTH(H4),DAY(H4)) -> 45322 | H4: =DATE(YEAR(I4)-1,MONTH(I4),DAY(I4)) -> 45688 | I4: 46053 | J4: =DATE(YEAR(I4)+1,MONTH(I4),DAY(I4)) -> 46418 | K4: =DATE(YEAR(J4)+1,MONTH(J4),DAY(J4)) -> 46783 | L4: =DATE(YEAR(K4)+1,MONTH(K4),DAY(K4)) -> 47149 | M4: =DATE(YEAR(L4)+1,MONTH(L4),DAY(L4)) -> 47514 | N4: =DATE(YEAR(M4)+1,MONTH(M4),DAY(M4)) -> 47879
E5: =2022 -> 2022 | F5: =E5+1 -> 2023 | G5: =F5+1 -> 2024 | H5: =G5+1 -> 2025 | I5: =H5+1 -> 2026
B7: Millions for the Year Ended January 31
C8: INCOME STATEMENT
B9: Continuing Operations
C10: revenue | E10: 4376.5 | F10: 5034 | G10: 5491 | H10: 6118.1 | I10: 6901.3
C11: credit account interest | E11: 249.4
C12: Revenue | E12: =E10+E11 -> 4625.9 | F12: =F10+F11 -> 5034 | G12: =G10+G11 -> 5491 | H12: =H10+H11 -> 6118.1 | I12: =I10+I11 -> 6901.3
C13: cost of sales | E13: 2625.3 | F13: 2827.7 | G13: 3034.5 | H13: 3456.5 | I13: 3847.5
C14: impairment losses on customer and other receivables | E14: 28.6 | F14: 31 | G14: 36 | H14: 19.4 | I14: 7.1
C15: Gross profit/(loss) | E15: =E12-E13-E14 -> 1972 | F15: =F12-F13-F14 -> 2175.3 | G15: =G12-G13-G14 -> 2420.5 | H15: =H12-H13-H14 -> 2642.2 | I15: =I12-I13-I14 -> 3046.7
C16: Distribution costs | E16: 693.7 | F16: 750 | G16: 794.1 | H16: 878.8 | I16: 1027.1
C17: Administrative expenses | E17: 380.2 | F17: 481.8 | G17: 657.7 | H17: 670.6 | I17: 742.4
C18: other losses/Gain-on financial instruments | E18: 2.5 | F18: -16.3 | G18: 12.3 | H18: 3.4 | I18: -3.4
C19: Trading profit | E19: =E15-E16-E17+E18 -> 900.6 | F19: =F15-F16-F17+F18 -> 927.2 | G19: =G15-G16-G17+G18 -> 981 | H19: =H15-H16-H17+H18 -> 1096.2 | I19: =I15-I16-I17+I18 -> 1273.8
C20: share of results of associates and joint ventures | E20: 4.8 | F20: 14.3 | G20: 6.9 | H20: 6.7 | I20: 7.9
C21: Impairment in associates and joint ventures | H21: -13 | I21: -2.9
C22: Exceptional items- curtailment loss | H22: -14.5
C23: Operating profit/(loss) | E23: =SUM(E19:E22) -> 905.4 | F23: =SUM(F19:F22) -> 941.5 | G23: =SUM(G19:G22) -> 987.9 | H23: =SUM(H19:H22) -> 1075.4 | I23: =SUM(I19:I22) -> 1278.8
C24: Gain on Reiss transaction- exceptional items | G24: 108.6
C25: Finance income | E25: 4.2 | F25: 5.7 | G25: 6.8 | H25: 8.2 | I25: 11
C26: finance costs | E26: -86.5 | F26: -77.9 | G26: -87.5 | H26: -96.6 | I26: -97.2
C27: Profit before taxation | E27: =SUM(E23:E26) -> 823.1 | F27: =SUM(F23:F26) -> 869.3 | G27: =SUM(G23:G26) -> 1015.8 | H27: =SUM(H23:H26) -> 987 | I27: =SUM(I23:I26) -> 1192.6
C28: Taxation | E28: -145.6 | F28: -158.6 | G28: -215.3 | H28: -243.8 | I28: -294.6
C29: Net Profit | E29: =SUM(E27:E28) -> 677.5 | F29: =SUM(F27:F28) -> 710.7 | G29: =SUM(G27:G28) -> 800.5 | H29: =SUM(H27:H28) -> 743.2 | I29: =SUM(I27:I28) -> 898
C32: Profit attributable to:
C33: Equity holders of the parent company | E33: 677.5 | F33: 711.7 | G33: 802.3 | H33: 736.1 | I33: 888.5
C34: non controlling interests | F34: -1 | G34: -1.8 | H34: 7.1 | I34: 9.5
E35: =SUM(E33:E34) -> 677.5 | F35: =SUM(F33:F34) -> 710.7 | G35: =SUM(G33:G34) -> 800.5 | H35: =SUM(H33:H34) -> 743.2 | I35: =SUM(I33:I34) -> 898
C36: Earnings/(losses) per share
C37: Basic | E37: 530.8p | F37: 573.4p | G37: 661.6p | H37: 615.1p | I37: 760.1p
C38: diluted | E38: 524.0p | F38: 570.5p | G38: 655.9p | H38: 605.5p | I38: 745.4p
C46: CASH-FLOW
C47: Cash flows from operating activities
C48: Operating profit | E48: 905.4 | F48: 941.5 | G48: 987.9 | H48: 1075.4 | I48: 1278.8
C49: Profit on disposal of associate | I49: -16.3
C50: Depreciation, impairment and (profit)/loss on disposal of property, plant and equipment | E50: 90.3 | F50: 80.6 | G50: 95.7 | H50: 117.9 | I50: 119.2
...

Sheet ASSUMPTIONS
C1: INPUT & ASSUMPTIONS | K1: =SCENARIOS!K1 -> CURRENTLY RUNNING: BULL / BEST CASE
M2: =COVER!B6 -> NEXT PLC
M3: ='MODEL&SCHEDULE'!M3 -> Bal Check: OK
E4: ='HISTORICAL FS'!E4 -> 44592 | F4: ='HISTORICAL FS'!F4 -> 44957 | G4: ='HISTORICAL FS'!G4 -> 45322 | H4: ='HISTORICAL FS'!H4 -> 45688 | I4: ='HISTORICAL FS'!I4 -> 46053 | J4: ='HISTORICAL FS'!J4 -> 46418 | K4: ='HISTORICAL FS'!K4 -> 46783 | L4: ='HISTORICAL FS'!L4 -> 47149 | ... N4: ='HISTORICAL FS'!N4 -> 47879
E5: ='HISTORICAL FS'!E5 -> 2022 | F5: ='HISTORICAL FS'!F5 -> 2023 | G5: ='HISTORICAL FS'!G5 -> 2024 | H5: ='HISTORICAL FS'!H5 -> 2025 | I5: ='HISTORICAL FS'!I5 -> 2026 | J5: =I5+1 -> 2027 | K5: =J5+1 -> 2028 | L5: =K5+1 -> 2029 | M5: =L5+1 -> 2030 | N5: =M5+1 -> 2031
C6: Line item description | D6: Notes/ source
C7: Days in the period | E7: =DATE(E5,12,31)-DATE(E5,1,1)+1 -> 365 | F7: =DATE(F5,12,31)-DATE(F5,1,1)+1 -> 365 | G7: =DATE(G5,12,31)-DATE(G5,1,1)+1 -> 366 | H7: =DATE(H5,12,31)-DATE(H5,1,1)+1 -> 365 | I7: =DATE(I5,12,31)-DATE(I5,1,1)+1 -> 365 | J7: =DATE(J5,12,31)-DATE(J5,1,1)+1 -> 365 | K7: =DATE(K5,12,31)-DATE(K5,1,1)+1 -> 366 | L7: =DATE(L5,12,31)-DATE(L5,1,1)+1 -> 365 | ... N7: =DATE(N5,12,31)-DATE(N5,1,1)+1 -> 365
C8: Million | D8: 1000000
C9: Nominal value of shares(p) | D9: 0.1
C10: Months in a year | D10: 12
B12: COLOR CODING SYSTEM
C13: Hard input (only in Assumptions tab) | D13: Blue text, no fill
C14: Percent | D14: 0.1
C15: Linked input | D15: no fill
C16: Formula | D16: Black text, no fill
C17: Check | D17: no fill
C18: Error/warning/ important detail | D18: Red text
C19: Units | D19: [$'m]
C20: Multiple | D20: 10
B21: GENERAL
C22: Forecast Period | D22: 5
C23: Cases
C24: BULL / BEST CASE
C25: BASE CASE
C26: BEAR / WORST CASE
B30: MACROECONOMIC ASSUMPTIONS
C31: UK GDP Growth Rate
C32: UK CPI Inflation
C33: BoE Base Rate
C34: Consumer Confidence
A36: INCOME STATEMENT ASSUMPTIONS
B37: REVENUE ASSUMPTIONS
C38: ='rough sheet'!C1045 -> SEGMENT
C39: ='rough sheet'!C1046 -> Online UK | D39: % | J39: 0.05 | K39: 0.07 | L39: 0.124 | M39: 0.092 | N39: 0.069
C40: ='rough sheet'!C1049 -> Online (International) | D40: % | J40: 0.053 | K40: 0.08 | L40: 0.072 | M40: 0.086 | N40: 0.098
C42: ='rough sheet'!C1053 -> Retail stores | D42: % | J42: -0.015 | K42: 0.019 | L42: 0.032 | M42: 0.038 | N42: 0.05
C43: ='rough sheet'!C1057 -> Next Finance/credit account interest | D43: % | J43: -0.017487733 | K43: -0.037 | L43: 0.007 | M43: 0.028 | N43: 0.06
C44: ='rough sheet'!C1060 -> Total Platform +next sale of investment | D44: % | J44: -0.15014254 | K44: -0.0558 | L44: -0.02296982 | M44: 0.11 | N44: 0.04141509
C45: ='rough sheet'!C1066 -> Other business Activities | D45: % | J45: 0.080296157 | K45: 0.07 | L45: 0.0285 | M45: 0.004 | N45: 0.034166667
C48: Credit Sales as a % of Product Revenue | D48: % | J48: 0.47792652 | K48: 0.46 | L48: 0.45 | M48: 0.47 | N48: 0.46
...

Sheet SCENARIOS
C1: SCENARIO ANALYSIS | K1: =_xlfn.CONCAT( " CURRENTLY RUNNING: ", " ",INDEX(L_Scenarios,S_Scenario,1)) -> CURRENTLY RUNNING: BULL / BEST CASE
M2: =COVER!B6 -> NEXT PLC
M3: ='MODEL&SCHEDULE'!M3 -> Bal Check: OK
J4: ='MODEL&SCHEDULE'!J4 -> 46418 | K4: ='MODEL&SCHEDULE'!K4 -> 46783 | L4: ='MODEL&SCHEDULE'!L4 -> 47149 | M4: ='MODEL&SCHEDULE'!M4 -> 47514 | N4: ='MODEL&SCHEDULE'!N4 -> 47879
J5: ='MODEL&SCHEDULE'!J5 -> 2027 | K5: ='MODEL&SCHEDULE'!K5 -> 2028 | L5: ='MODEL&SCHEDULE'!L5 -> 2029 | M5: ='MODEL&SCHEDULE'!M5 -> 2030 | N5: ='MODEL&SCHEDULE'!N5 -> 2031
C8: SCENARIO SWITCH | D8: 1
C15: =ASSUMPTIONS!C24 -> BULL / BEST CASE
C16: =ASSUMPTIONS!C25 -> BASE CASE
C17: =ASSUMPTIONS!C26 -> BEAR / WORST CASE
C20: Sales :
C21: Online UK | J21: {=INDEX(J23:J25,S_Scenario)} -> 0.05 | K21: {=INDEX(K23:K25,S_Scenario)} -> 0.1 | L21: {=INDEX(L23:L25,S_Scenario)} -> 0.164 | M21: {=INDEX(M23:M25,S_Scenario)} -> 0.12 | N21: {=INDEX(N23:N25,S_Scenario)} -> 0.08
C23: =ASSUMPTIONS!C24 -> BULL / BEST CASE | J23: 0.05 | K23: 0.1 | L23: 0.164 | M23: 0.12 | N23: 0.08
C24: =ASSUMPTIONS!C25 -> BASE CASE | J24: 0.04500657 | K24: 0.07 | L24: 0.08 | M24: 0.102 | N24: 0.069
C25: =ASSUMPTIONS!C26 -> BEAR / WORST CASE | J25: 0.035 | K25: 0.04 | L25: 0.03 | M25: 0.05 | N25: 0.04
C29: Online UK International | J29: {=INDEX(J31:J33,S_Scenario)} -> 0.143 | K29: {=INDEX(K31:K33,S_Scenario)} -> 0.15 | L29: {=INDEX(L31:L33,S_Scenario)} -> 0.15 | M29: {=INDEX(M31:M33,S_Scenario)} -> 0.08 | N29: {=INDEX(N31:N33,S_Scenario)} -> 0.12
C31: =C23 -> BULL / BEST CASE | J31: 0.143 | K31: 0.15 | L31: 0.15 | M31: 0.08 | N31: 0.12
C32: =C24 -> BASE CASE | J32: 0.13903546 | K32: 0.08 | L32: 0.132 | M32: 0.056 | N32: 0.098
C33: =C25 -> BEAR / WORST CASE | J33: 0.04 | K33: 0.06 | L33: 0.1 | M33: 0.03 | N33: 0.04
C36: Finance Interest Income
J37: {=INDEX(J39:J41,S_Scenario)} -> 0.02 | K37: {=INDEX(K39:K41,S_Scenario)} -> 0.01 | L37: {=INDEX(L39:L41,S_Scenario)} -> 0.03 | M37: {=INDEX(M39:M41,S_Scenario)} -> 0.04 | N37: {=INDEX(N39:N41,S_Scenario)} -> 0.08
C39: =C31 -> BULL / BEST CASE | J39: 0.02 | K39: 0.01 | L39: 0.03 | M39: 0.04 | N39: 0.08
C40: =C32 -> BASE CASE | J40: -0.017487733 | K40: -0.037 | L40: 0.007 | M40: 0.028 | N40: 0.06
C41: =C33 -> BEAR / WORST CASE | J41: -0.04 | K41: -0.05 | L41: -0.03 | M41: 0 | N41: 0.03
C45: Retail | J45: {=INDEX(J47:J49,S_Scenario)} -> 0.01 | K45: {=INDEX(K47:K49,S_Scenario)} -> 0.03 | L45: {=INDEX(L47:L49,S_Scenario)} -> 0.048 | M45: {=INDEX(M47:M49,S_Scenario)} -> 0.005 | N45: {=INDEX(N47:N49,S_Scenario)} -> 0.07
C47: =C39 -> BULL / BEST CASE | J47: 0.01 | K47: 0.03 | L47: 0.048 | M47: 0.005 | N47: 0.07
C48: =C40 -> BASE CASE | J48: -0.020495233 | K48: 0.019 | L48: 0.032 | M48: -0.02 | N48: 0.05
C49: =C41 -> BEAR / WORST CASE | J49: -0.04 | K49: -0.02 | L49: 0.01 | M49: -0.04 | N49: 0.03
C54: Total platform | J54: {=INDEX(J56:J58,S_Scenario)} -> 0.046 | K54: {=INDEX(K56:K58,S_Scenario)} -> 0.15 | L54: {=INDEX(L56:L58,S_Scenario)} -> 0.023 | M54: {=INDEX(M56:M58,S_Scenario)} -> 0.22 | N54: {=INDEX(N56:N58,S_Scenario)} -> 0.05
C56: =C47 -> BULL / BEST CASE | J56: 0.046 | K56: 0.15 | L56: 0.023 | M56: 0.22 | N56: 0.05
C57: =C48 -> BASE CASE | J57: -0.11014254 | K57: 0.1058 | L57: -0.02296982 | M57: 0.2 | N57: 0.04141509
C58: =C49 -> BEAR / WORST CASE | J58: -0.14 | K58: 0.05 | L58: -0.031 | M58: 0.08 | N58: 0.03
C62: Other Business Activities | J62: {=INDEX(J64:J66,S_Scenario)} -> 0.03 | K62: {=INDEX(K64:K66,S_Scenario)} -> 0.09 | L62: {=INDEX(L64:L66,S_Scenario)} -> 0.05 | M62: {=INDEX(M64:M66,S_Scenario)} -> 0.03 | N62: {=INDEX(N64:N66,S_Scenario)} -> 0.05
C64: =C47 -> BULL / BEST CASE | J64: 0.03 | K64: 0.09 | L64: 0.05 | M64: 0.03 | N64: 0.05
C65: =C48 -> BASE CASE | J65: 0.010296157 | K65: 0.07 | L65: 0.0285 | M65: 0.004 | N65: 0.034166667
C66: =C49 -> BEAR / WORST CASE | J66: -0.0079 | K66: 0.05 | L66: -0.012 | M66: -0.022 | N66: 0
C71: Capex | J71: {=INDEX(J73:J75,S_Scenario)} -> 300 | K71: {=INDEX(K73:K75,S_Scenario)} -> 300 | L71: {=INDEX(L73:L75,S_Scenario)} -> 300 | M71: {=INDEX(M73:M75,S_Scenario)} -> 300 | N71: {=INDEX(N73:N75,S_Scenario)} -> 400
C73: =C64 -> BULL / BEST CASE | J73: 300 | K73: 300 | L73: 300 | M73: 300 | N73: 400
C74: =C65 -> BASE CASE | J74: 237 | K74: 245 | L74: 220 | M74: 270 | N74: 300
C75: =C66 -> BEAR / WORST CASE | J75: 200 | K75: 200 | L75: 180 | M75: 200 | N75: 200
C79: Buyback | J79: {=INDEX(J81:J83,S_Scenario)} -> 550 | K79: {=INDEX(K81:K83,S_Scenario)} -> 400 | L79: {=INDEX(L81:L83,S_Scenario)} -> 300 | M79: {=INDEX(M81:M83,S_Scenario)} -> 400 | N79: {=INDEX(N81:N83,S_Scenario)} -> 400
...

Sheet MODEL&SCHEDULE
C1: FINANCIAL STATEMENTS & SCHEDULES | K1: =SCENARIOS!K1 -> CURRENTLY RUNNING: BULL / BEST CASE
M2: =COVER!B6 -> NEXT PLC
M3: =IF(Balcheck=0, "Bal Check: OK", "ERROR") -> Bal Check: OK
E4: =ASSUMPTIONS!E4 -> 44592 | F4: =ASSUMPTIONS!F4 -> 44957 | G4: =ASSUMPTIONS!G4 -> 45322 | H4: =ASSUMPTIONS!H4 -> 45688 | I4: =ASSUMPTIONS!I4 -> 46053 | J4: =ASSUMPTIONS!J4 -> 46418 | K4: =ASSUMPTIONS!K4 -> 46783 | L4: =ASSUMPTIONS!L4 -> 47149 | ... N4: =ASSUMPTIONS!N4 -> 47879
E5: =ASSUMPTIONS!E5 -> 2022 | F5: =ASSUMPTIONS!F5 -> 2023 | G5: =ASSUMPTIONS!G5 -> 2024 | H5: =ASSUMPTIONS!H5 -> 2025 | I5: =ASSUMPTIONS!I5 -> 2026 | J5: =ASSUMPTIONS!J5 -> 2027 | K5: =ASSUMPTIONS!K5 -> 2028 | L5: =ASSUMPTIONS!L5 -> 2029 | ... N5: =ASSUMPTIONS!N5 -> 2031
B6: ='HISTORICAL FS'!B7 -> Millions for the Year Ended January 31 | C6: INCOME- STATEMENT
C8: ='rough sheet'!C744 -> SEGMENT
C9: ='rough sheet'!C745 -> Online UK | H9: ='rough sheet'!H745 -> 2302.7 | I9: ='rough sheet'!I745 -> 2587.4 | J9: =I9*(1+SCENARIOS!J21) -> 2716.77 | K9: =J9*(1+SCENARIOS!K21) -> 2988.447 | L9: =K9*(1+SCENARIOS!L21) -> 3478.5523 | M9: =L9*(1+SCENARIOS!M21) -> 3895.9786 | N9: =M9*(1+SCENARIOS!N21) -> 4207.6569
C10: ='rough sheet'!C746 -> Online (International) | H10: ='rough sheet'!H746 -> 898.5 | I10: ='rough sheet'!I746 -> 1280.4 | J10: =I10*(1+SCENARIOS!J29) -> 1463.4972 | K10: =J10*(1+SCENARIOS!K29) -> 1683.0218 | L10: =K10*(1+SCENARIOS!L29) -> 1935.475 | M10: =L10*(1+SCENARIOS!M29) -> 2090.3131 | N10: =M10*(1+SCENARIOS!N29) -> 2341.1506
C11: ='rough sheet'!C747 -> Next Online | E11: ='rough sheet'!E747 -> 2863.1 | F11: ='rough sheet'!F747 -> 2743.6 | G11: ='rough sheet'!G747 -> 2901.4 | H11: =SUM(H9:H10) -> 3201.2 | I11: =SUM(I9:I10) -> 3867.8 | J11: =SUM(J9:J10) -> 4180.2672 | K11: =SUM(K9:K10) -> 4671.4688 | L11: =SUM(L9:L10) -> 5414.0274 | M11: =SUM(M9:M10) -> 5986.2916 | N11: =SUM(N9:N10) -> 6548.8075
C12: ='rough sheet'!C748 -> Next Retail | E12: ='rough sheet'!E748 -> 1425.9 | F12: ='rough sheet'!F748 -> 1849.1 | G12: ='rough sheet'!G748 -> 1843.7 | H12: ='rough sheet'!H748 -> 1821.2 | I12: ='rough sheet'!I748 -> 1888 | J12: =I12*(1+SCENARIOS!J45) -> 1906.88 | K12: =J12*(1+SCENARIOS!K45) -> 1964.0864 | L12: =K12*(1+SCENARIOS!L45) -> 2058.3625 | M12: =L12*(1+SCENARIOS!M45) -> 2068.6544 | N12: =M12*(1+SCENARIOS!N45) -> 2213.4602
C13: ='rough sheet'!C749 -> Product Revenue | E13: =E11+E12 -> 4289 | F13: =F11+F12 -> 4592.7 | G13: =G11+G12 -> 4745.1 | H13: =H11+H12 -> 5022.4 | I13: =I11+I12 -> 5755.8 | J13: =J11+J12 -> 6087.1472 | K13: =K11+K12 -> 6635.5552 | L13: =L11+L12 -> 7472.3899 | ... N13: =N11+N12 -> 8762.2677
C14: ='rough sheet'!C750 -> Next Finance/credit account interest | E14: ='rough sheet'!E750 -> 249.4 | F14: ='rough sheet'!F750 -> 274.4 | G14: ='rough sheet'!G750 -> 292.7 | H14: ='rough sheet'!H750 -> 301 | I14: ='rough sheet'!I750 -> 305.7 | J14: =I14*(1+SCENARIOS!J37) -> 311.814 | K14: =J14*(1+SCENARIOS!K37) -> 314.93214 | L14: =K14*(1+SCENARIOS!L37) -> 324.3801 | M14: =L14*(1+SCENARIOS!M37) -> 337.35531 | N14: =M14*(1+SCENARIOS!N37) -> 364.34373
C15: ='rough sheet'!C751 -> Total Platform +next sale of investment | E15: ='rough sheet'!E751 -> 11.3 | F15: ='rough sheet'!F751 -> 75.7 | G15: ='rough sheet'!G751 -> 363.8 | H15: ='rough sheet'!H751 -> 690 | I15: ='rough sheet'!I751 -> 734.3 | J15: =I15*(1+SCENARIOS!J54) -> 768.0778 | K15: =J15*(1+SCENARIOS!K54) -> 883.28947 | L15: =K15*(1+SCENARIOS!L54) -> 903.60513 | M15: =L15*(1+SCENARIOS!M54) -> 1102.3983 | N15: =M15*(1+SCENARIOS!N54) -> 1157.5182
C16: ='rough sheet'!C752 -> Other business Activities | E16: ='rough sheet'!E752 -> 76.2 | F16: ='rough sheet'!F752 -> 91.2 | G16: ='rough sheet'!G752 -> 89.4 | H16: ='rough sheet'!H752 -> 104.7 | I16: ='rough sheet'!I752 -> 105.5 | J16: =I16*(1+SCENARIOS!J62) -> 108.665 | K16: =J16*(1+SCENARIOS!K62) -> 118.44485 | L16: =K16*(1+SCENARIOS!L62) -> 124.36709 | M16: =L16*(1+SCENARIOS!M62) -> 128.09811 | N16: =M16*(1+SCENARIOS!N62) -> 134.50301
C17: ='HISTORICAL FS'!C12 -> Revenue | E17: =E13+E14+E15+E16 -> 4625.9 | F17: =F13+F14+F15+F16 -> 5034 | G17: =G13+G14+G15+G16 -> 5491 | H17: =H13+H14+H15+H16 -> 6118.1 | I17: =I13+I14+I15+I16 -> 6901.3 | J17: =J13+J14+J15+J16 -> 7275.704 | K17: =K13+K14+K15+K16 -> 7952.2216 | L17: =L13+L14+L15+L16 -> 8824.7422 | ... N17: =N13+N14+N15+N16 -> 10418.633
C18: ='HISTORICAL FS'!C13 -> cost of sales | E18: ='HISTORICAL FS'!E13 -> 2625.3 | F18: ='HISTORICAL FS'!F13 -> 2827.7 | G18: ='HISTORICAL FS'!G13 -> 3034.5 | H18: ='HISTORICAL FS'!H13 -> 3456.5 | I18: ='HISTORICAL FS'!I13 -> 3847.5 | J18: =J17*ASSUMPTIONS!$J$55 -> 4080.7103 | K18: =K17*ASSUMPTIONS!$J$55 -> 4460.1475 | L18: =L17*ASSUMPTIONS!$J$55 -> 4949.5164 | M18: =M17*ASSUMPTIONS!$J$55 -> 5397.1203 | N18: =N17*ASSUMPTIONS!$J$55 -> 5843.4787
C19: ='HISTORICAL FS'!C14 -> impairment losses on customer and other receivables | E19: ='HISTORICAL FS'!E14 -> 28.6 | F19: ='HISTORICAL FS'!F14 -> 31 | G19: ='HISTORICAL FS'!G14 -> 36 | H19: ='HISTORICAL FS'!H14 -> 19.4 | I19: ='HISTORICAL FS'!I14 -> 7.1 | J19: 0 | K19: =J19 -> 0 | L19: =K19 -> 0 | M19: =L19 -> 0 | N19: =M19 -> 0
C20: ='HISTORICAL FS'!C15 -> Gross profit/(loss) | E20: =E17-E18-E19 -> 1972 | F20: =F17-F18-F19 -> 2175.3 | G20: =G17-G18-G19 -> 2420.5 | H20: =H17-H18-H19 -> 2642.2 | I20: =I17-I18-I19 -> 3046.7 | J20: =J17-J18-J19 -> 3194.9937 | K20: =K17-K18-K19 -> 3492.0742 | L20: =L17-L18-L19 -> 3875.2258 | ... N20: =N17-N18-N19 -> 4575.1539
C21: ='HISTORICAL FS'!C16 -> Distribution costs | E21: ='HISTORICAL FS'!E16 -> 693.7 | F21: ='HISTORICAL FS'!F16 -> 750 | G21: ='HISTORICAL FS'!G16 -> 794.1 | H21: ='HISTORICAL FS'!H16 -> 878.8 | I21: ='HISTORICAL FS'!I16 -> 1027.1 | J21: =J17*ASSUMPTIONS!$J$57 -> 1071.0298 | K21: =K17*ASSUMPTIONS!$J$57 -> 1170.6175 | L21: =L17*ASSUMPTIONS!$J$57 -> 1299.0581 | M21: =M17*ASSUMPTIONS!$J$57 -> 1416.5369 | N21: =N17*ASSUMPTIONS!$J$57 -> 1533.6889
C22: ='HISTORICAL FS'!C17 -> Administrative expenses | E22: ='HISTORICAL FS'!E17 -> 380.2 | F22: ='HISTORICAL FS'!F17 -> 481.8 | G22: ='HISTORICAL FS'!G17 -> 657.7 | H22: ='HISTORICAL FS'!H17 -> 670.6 | I22: ='HISTORICAL FS'!I17 -> 742.4 | J22: =J17*ASSUMPTIONS!$J$58 -> 749.19312 | K22: =K17*ASSUMPTIONS!$J$58 -> 818.85543 | L22: =L17*ASSUMPTIONS!$J$58 -> 908.70054 | M22: =M17*ASSUMPTIONS!$J$58 -> 990.87783 | N22: =N17*ASSUMPTIONS!$J$58 -> 1072.8265
C23: ='HISTORICAL FS'!C18 -> other losses/Gain-on financial instruments | E23: ='HISTORICAL FS'!E18 -> 2.5 | F23: ='HISTORICAL FS'!F18 -> -16.3 | G23: ='HISTORICAL FS'!G18 -> 12.3 | H23: ='HISTORICAL FS'!H18 -> 3.4 | I23: ='HISTORICAL FS'!I18 -> -3.4 | J23: 0 | K23: 0 | L23: 0 | M23: 0 | N23: 0
C24: ='HISTORICAL FS'!C19 -> Trading profit | E24: =E20-E21-E22+E23 -> 900.6 | F24: =F20-F21-F22+F23 -> 927.2 | G24: =G20-G21-G22+G23 -> 981 | H24: =H20-H21-H22+H23 -> 1096.2 | I24: =I20-I21-I22+I23 -> 1273.8 | J24: =J20-J21-J22+J23 -> 1374.7707 | K24: =K20-K21-K22+K23 -> 1502.6012 | L24: =L20-L21-L22+L23 -> 1667.4671 | ... N24: =N20-N21-N22+N23 -> 1968.6385
C25: ='HISTORICAL FS'!C20 -> share of results of associates and joint ventures | E25: ='HISTORICAL FS'!E20 -> 4.8 | F25: ='HISTORICAL FS'!F20 -> 14.3 | G25: ='HISTORICAL FS'!G20 -> 6.9 | H25: ='HISTORICAL FS'!H20 -> 6.7 | I25: ='HISTORICAL FS'!I20 -> 7.9 | J25: =J389 -> 5.7997423 | K25: =K389 -> 6.7553392 | L25: =L389 -> 7.8683854 | M25: =M389 -> 9.1648232 | N25: =N389 -> 10.674869
C26: ='HISTORICAL FS'!C21 -> Impairment in associates and joint ventures | H26: ='HISTORICAL FS'!H21 -> -13 | I26: ='HISTORICAL FS'!I21 -> -2.9 | J26: =ASSUMPTIONS!J134 -> 0 | K26: =J26 -> 0 | L26: =K26 -> 0 | M26: =L26 -> 0 | N26: =M26 -> 0
C27: ='HISTORICAL FS'!C22 -> Exceptional items- curtailment loss | H27: ='HISTORICAL FS'!H22 -> -14.5 | I27: ='HISTORICAL FS'!I22 -> 0 | J27: =I27 -> 0 | K27: =J27 -> 0 | L27: =K27 -> 0 | M27: =L27 -> 0 | N27: =M27 -> 0
C28: ='HISTORICAL FS'!C23 -> Operating profit/(loss) | E28: =SUM(E24:E27) -> 905.4 | F28: =SUM(F24:F27) -> 941.5 | G28: =SUM(G24:G27) -> 987.9 | H28: =SUM(H24:H27) -> 1075.4 | I28: =SUM(I24:I27) -> 1278.8 | J28: =SUM(J24:J27) -> 1380.5705 | K28: =SUM(K24:K27) -> 1509.3565 | L28: =SUM(L24:L27) -> 1675.3355 | ... N28: =SUM(N24:N27) -> 1979.3134
C29: ='HISTORICAL FS'!C24 -> Gain on Reiss transaction- exceptional items | G29: ='HISTORICAL FS'!G24 -> 108.6 | J29: 0 | K29: =J29 -> 0 | L29: =K29 -> 0 | M29: =L29 -> 0 | N29: =M29 -> 0
C30: ='HISTORICAL FS'!C25 -> Finance income | E30: ='HISTORICAL FS'!E25 -> 4.2 | F30: ='HISTORICAL FS'!F25 -> 5.7 | G30: ='HISTORICAL FS'!G25 -> 6.8 | H30: ='HISTORICAL FS'!H25 -> 8.2 | I30: ='HISTORICAL FS'!I25 -> 11 | J30: =J560 -> 3.6075 | K30: =K560 -> 4.078389 | L30: =L560 -> 8.006496 | M30: =M560 -> 9.1450894 | N30: =N560 -> 20.045055
C31: ='HISTORICAL FS'!C26 -> finance costs | E31: =-'HISTORICAL FS'!E26 -> 86.5 | F31: =-'HISTORICAL FS'!F26 -> 77.9 | G31: =-'HISTORICAL FS'!G26 -> 87.5 | H31: =-'HISTORICAL FS'!H26 -> 96.6 | I31: =-'HISTORICAL FS'!I26 -> 97.2 | J31: =J554 -> -19.459936 | K31: =K554 -> -20.93962 | L31: =L554 -> -28.678782 | M31: =M554 -> -29.824309 | N31: =N554 -> -28.241797
C32: ='HISTORICAL FS'!C27 -> Profit before taxation | E32: =E28+E29+E30-E31 -> 823.1 | F32: =F28+F29+F30-F31 -> 869.3 | G32: =G28+G29+G30-G31 -> 1015.8 | H32: =H28+H29+H30-H31 -> 987 | I32: =I28+I29+I30-I31 -> 1192.6 | J32: =J28+J29+J30-J31 -> 1403.6379 | K32: =K28+K29+K30-K31 -> 1534.3746 | L32: =L28+L29+L30-L31 -> 1712.0208 | ... N32: =N28+N29+N30-N31 -> 2027.6002
C33: ='HISTORICAL FS'!C28 -> Taxation | E33: =-'HISTORICAL FS'!E28 -> 145.6 | F33: =-'HISTORICAL FS'!F28 -> 158.6 | G33: =-'HISTORICAL FS'!G28 -> 215.3 | H33: =-'HISTORICAL FS'!H28 -> 243.8 | I33: =-'HISTORICAL FS'!I28 -> 294.6 | J33: =J428 -> 350.90948 | K33: =K428 -> 383.59364 | L33: =L428 -> 428.0052 | M33: =M428 -> 466.59921 | N33: =N428 -> 506.90006
C34: ='HISTORICAL FS'!C29 -> Net Profit | E34: =E32-E33 -> 677.5 | F34: =F32-F33 -> 710.7 | G34: =G32-G33 -> 800.5 | H34: =H32-H33 -> 743.2 | I34: =I32-I33 -> 898 | J34: =J32-J33 -> 1052.7284 | K34: =K32-K33 -> 1150.7809 | L34: =L32-L33 -> 1284.0156 | ... N34: =N32-N33 -> 1520.7002
C36: ='HISTORICAL FS'!C32 -> Profit attributable to:
C37: ='HISTORICAL FS'!C33 -> Equity holders of the parent company | E37: ='HISTORICAL FS'!E33 -> 677.5 | F37: ='HISTORICAL FS'!F33 -> 711.7 | G37: ='HISTORICAL FS'!G33 -> 802.3 | H37: ='HISTORICAL FS'!H33 -> 736.1 | I37: ='HISTORICAL FS'!I33 -> 888.5 | J37: =J34-J38 -> 1041.4938 | K37: =K34-K38 -> 1137.7566 | L37: =L34-L38 -> 1268.2951 | M37: =M34-M38 -> 1381.7048 | N37: =N34-N38 -> 1500.4139
C38: ='HISTORICAL FS'!C34 -> non controlling interests | E38: ='HISTORICAL FS'!E34 -> 0 | F38: ='HISTORICAL FS'!F34 -> -1 | G38: ='HISTORICAL FS'!G34 -> -1.8 | H38: ='HISTORICAL FS'!H34 -> 7.1 | I38: ='HISTORICAL FS'!I34 -> 9.5 | J38: =J541 -> 11.23463 | K38: =K541 -> 13.024306 | L38: =L541 -> 15.720498 | M38: =M541 -> 18.092806 | N38: =N541 -> 20.286279
E39: =SUM(E37:E38) -> 677.5 | F39: =SUM(F37:F38) -> 710.7 | G39: =SUM(G37:G38) -> 800.5 | H39: =SUM(H37:H38) -> 743.2 | I39: =SUM(I37:I38) -> 898 | J39: =SUM(J37:J38) -> 1052.7284 | K39: =SUM(K37:K38) -> 1150.7809 | L39: =SUM(L37:L38) -> 1284.0156 | ... N39: =SUM(N37:N38) -> 1520.7002
C40: ='HISTORICAL FS'!C36 -> Earnings/(losses) per share
C41: ='HISTORICAL FS'!C37 -> Basic
C42: ='HISTORICAL FS'!C38 -> diluted
...

Sheet SENSITIVITY
C1: SENSITIVITY ANALYSIS | K1: ='MODEL&SCHEDULE'!K1 -> CURRENTLY RUNNING: BULL / BEST CASE
C2: TORNADO CHART, ONE WAY & 2 WAY | M2: ='MODEL&SCHEDULE'!M2 -> NEXT PLC
M3: ='MODEL&SCHEDULE'!M3 -> Bal Check: OK
J4: ='MODEL&SCHEDULE'!J4 -> 46418 | K4: ='MODEL&SCHEDULE'!K4 -> 46783 | L4: ='MODEL&SCHEDULE'!L4 -> 47149 | M4: ='MODEL&SCHEDULE'!M4 -> 47514 | N4: ='MODEL&SCHEDULE'!N4 -> 47879
J5: ='MODEL&SCHEDULE'!J5 -> 2027 | K5: ='MODEL&SCHEDULE'!K5 -> 2028 | L5: ='MODEL&SCHEDULE'!L5 -> 2029 | M5: ='MODEL&SCHEDULE'!M5 -> 2030 | N5: ='MODEL&SCHEDULE'!N5 -> 2031
C7: Tornado Chart | I7: One-way Analysis | Q7: Two-way Analysis
D8: =R8 -> 2027 ONLY using the Whole Revenue | J8: ACROSS ALL YEARS | R8: 2027 ONLY using the Whole Revenue
U9: =L10 -> EBIAT/NOPAT
L10: =C92 -> EBIAT/NOPAT | Q10: Online UK Revenue Growth | T10: EBIT margin
I11: Online UK Revenue Growth | Q11: =I96*(1+J97)*(J88*(1-J90)) -> 1035.4279 | R11: 0.175 | S11: 0.18 | T11: 0.185 | U11: 0.18980011 | V11: 0.19 | W11: 0.195 | X11: 0.2
I12: 0.03 | J12: =('MODEL&SCHEDULE'!J$17-SENSITIVITY!I$85*SENSITIVITY!J$87+SENSITIVITY!I$85*SENSITIVITY!$I12)*(SENSITIVITY!J$88*(1-SENSITIVITY!$J$90)) -> 1028.0634 | K12: =('MODEL&SCHEDULE'!K$17-SENSITIVITY!J$85*SENSITIVITY!K$87+SENSITIVITY!J$85*SENSITIVITY!$I12)*(SENSITIVITY!K$88*(1-SENSITIVITY!$J$90)) -> 1104.9457 | L12: =('MODEL&SCHEDULE'!L$17-SENSITIVITY!K$85*SENSITIVITY!L$87+SENSITIVITY!K$85*SENSITIVITY!$I12)*(SENSITIVITY!L$88*(1-SENSITIVITY!$J$90)) -> 1199.4837 | M12: =('MODEL&SCHEDULE'!M$17-SENSITIVITY!L$85*SENSITIVITY!M$87+SENSITIVITY!L$85*SENSITIVITY!$I12)*(SENSITIVITY!M$88*(1-SENSITIVITY!$J$90)) -> 1325.9802 | N12: =('MODEL&SCHEDULE'!N$17-SENSITIVITY!M$85*SENSITIVITY!N$87+SENSITIVITY!M$85*SENSITIVITY!$I12)*(SENSITIVITY!N$88*(1-SENSITIVITY!$J$90)) -> 1456.7294 | Q12: -0.02 | R12: 887.67971 | S12: 913.04199 | T12: 938.40427 | U12: 962.75259 | V12: 963.76655 | W12: 989.12882 | X12: 1014.4911
I13: 0.04 | J13: =('MODEL&SCHEDULE'!J$17-SENSITIVITY!I$85*SENSITIVITY!J$87+SENSITIVITY!I$85*SENSITIVITY!$I13)*(SENSITIVITY!J$88*(1-SENSITIVITY!$J$90)) -> 1031.7457 | K13: =('MODEL&SCHEDULE'!K$17-SENSITIVITY!J$85*SENSITIVITY!K$87+SENSITIVITY!J$85*SENSITIVITY!$I13)*(SENSITIVITY!K$88*(1-SENSITIVITY!$J$90)) -> 1108.8131 | L13: =('MODEL&SCHEDULE'!L$17-SENSITIVITY!K$85*SENSITIVITY!L$87+SENSITIVITY!K$85*SENSITIVITY!$I13)*(SENSITIVITY!L$88*(1-SENSITIVITY!$J$90)) -> 1203.7388 | M13: =('MODEL&SCHEDULE'!M$17-SENSITIVITY!L$85*SENSITIVITY!M$87+SENSITIVITY!L$85*SENSITIVITY!$I13)*(SENSITIVITY!M$88*(1-SENSITIVITY!$J$90)) -> 1330.9347 | N13: =('MODEL&SCHEDULE'!N$17-SENSITIVITY!M$85*SENSITIVITY!N$87+SENSITIVITY!M$85*SENSITIVITY!$I13)*(SENSITIVITY!N$88*(1-SENSITIVITY!$J$90)) -> 1462.2805 | Q13: -0.01 | R13: 896.73767 | S13: 922.35875 | T13: 947.97982 | U13: 972.5766 | V13: 973.6009 | W13: 999.22197 | X13: 1024.8431
I14: 0.05 | J14: =('MODEL&SCHEDULE'!J$17-SENSITIVITY!I$85*SENSITIVITY!J$87+SENSITIVITY!I$85*SENSITIVITY!$I14)*(SENSITIVITY!J$88*(1-SENSITIVITY!$J$90)) -> 1035.4279 | K14: =('MODEL&SCHEDULE'!K$17-SENSITIVITY!J$85*SENSITIVITY!K$87+SENSITIVITY!J$85*SENSITIVITY!$I14)*(SENSITIVITY!K$88*(1-SENSITIVITY!$J$90)) -> 1112.6805 | L14: =('MODEL&SCHEDULE'!L$17-SENSITIVITY!K$85*SENSITIVITY!L$87+SENSITIVITY!K$85*SENSITIVITY!$I14)*(SENSITIVITY!L$88*(1-SENSITIVITY!$J$90)) -> 1207.9939 | M14: =('MODEL&SCHEDULE'!M$17-SENSITIVITY!L$85*SENSITIVITY!M$87+SENSITIVITY!L$85*SENSITIVITY!$I14)*(SENSITIVITY!M$88*(1-SENSITIVITY!$J$90)) -> 1335.8892 | N14: =('MODEL&SCHEDULE'!N$17-SENSITIVITY!M$85*SENSITIVITY!N$87+SENSITIVITY!M$85*SENSITIVITY!$I14)*(SENSITIVITY!N$88*(1-SENSITIVITY!$J$90)) -> 1467.8316 | Q14: 0 | R14: 905.79562 | S14: 931.6755 | T14: 957.55537 | U14: 982.40061 | V14: 983.43525 | W14: 1009.3151 | X14: 1035.195
I15: 0.06 | J15: =('MODEL&SCHEDULE'!J$17-SENSITIVITY!I$85*SENSITIVITY!J$87+SENSITIVITY!I$85*SENSITIVITY!$I15)*(SENSITIVITY!J$88*(1-SENSITIVITY!$J$90)) -> 1039.1101 | K15: =('MODEL&SCHEDULE'!K$17-SENSITIVITY!J$85*SENSITIVITY!K$87+SENSITIVITY!J$85*SENSITIVITY!$I15)*(SENSITIVITY!K$88*(1-SENSITIVITY!$J$90)) -> 1116.5479 | L15: =('MODEL&SCHEDULE'!L$17-SENSITIVITY!K$85*SENSITIVITY!L$87+SENSITIVITY!K$85*SENSITIVITY!$I15)*(SENSITIVITY!L$88*(1-SENSITIVITY!$J$90)) -> 1212.2489 | M15: =('MODEL&SCHEDULE'!M$17-SENSITIVITY!L$85*SENSITIVITY!M$87+SENSITIVITY!L$85*SENSITIVITY!$I15)*(SENSITIVITY!M$88*(1-SENSITIVITY!$J$90)) -> 1340.8437 | N15: =('MODEL&SCHEDULE'!N$17-SENSITIVITY!M$85*SENSITIVITY!N$87+SENSITIVITY!M$85*SENSITIVITY!$I15)*(SENSITIVITY!N$88*(1-SENSITIVITY!$J$90)) -> 1473.3828 | Q15: 0.01 | R15: 914.85358 | S15: 940.99226 | T15: 967.13093 | U15: 992.22461 | V15: 993.2696 | W15: 1019.4083 | X15: 1045.547
I16: 0.07 | J16: =('MODEL&SCHEDULE'!J$17-SENSITIVITY!I$85*SENSITIVITY!J$87+SENSITIVITY!I$85*SENSITIVITY!$I16)*(SENSITIVITY!J$88*(1-SENSITIVITY!$J$90)) -> 1042.7923 | K16: =('MODEL&SCHEDULE'!K$17-SENSITIVITY!J$85*SENSITIVITY!K$87+SENSITIVITY!J$85*SENSITIVITY!$I16)*(SENSITIVITY!K$88*(1-SENSITIVITY!$J$90)) -> 1120.4153 | L16: =('MODEL&SCHEDULE'!L$17-SENSITIVITY!K$85*SENSITIVITY!L$87+SENSITIVITY!K$85*SENSITIVITY!$I16)*(SENSITIVITY!L$88*(1-SENSITIVITY!$J$90)) -> 1216.504 | M16: =('MODEL&SCHEDULE'!M$17-SENSITIVITY!L$85*SENSITIVITY!M$87+SENSITIVITY!L$85*SENSITIVITY!$I16)*(SENSITIVITY!M$88*(1-SENSITIVITY!$J$90)) -> 1345.7982 | N16: =('MODEL&SCHEDULE'!N$17-SENSITIVITY!M$85*SENSITIVITY!N$87+SENSITIVITY!M$85*SENSITIVITY!$I16)*(SENSITIVITY!N$88*(1-SENSITIVITY!$J$90)) -> 1478.9339 | Q16: 0.02 | R16: 923.91154 | S16: 950.30901 | T16: 976.70648 | U16: 1002.0486 | V16: 1003.104 | W16: 1029.5014 | X16: 1055.8989
I17: 0.08 | J17: =('MODEL&SCHEDULE'!J$17-SENSITIVITY!I$85*SENSITIVITY!J$87+SENSITIVITY!I$85*SENSITIVITY!$I17)*(SENSITIVITY!J$88*(1-SENSITIVITY!$J$90)) -> 1046.4745 | K17: =('MODEL&SCHEDULE'!K$17-SENSITIVITY!J$85*SENSITIVITY!K$87+SENSITIVITY!J$85*SENSITIVITY!$I17)*(SENSITIVITY!K$88*(1-SENSITIVITY!$J$90)) -> 1124.2826 | L17: =('MODEL&SCHEDULE'!L$17-SENSITIVITY!K$85*SENSITIVITY!L$87+SENSITIVITY!K$85*SENSITIVITY!$I17)*(SENSITIVITY!L$88*(1-SENSITIVITY!$J$90)) -> 1220.7591 | M17: =('MODEL&SCHEDULE'!M$17-SENSITIVITY!L$85*SENSITIVITY!M$87+SENSITIVITY!L$85*SENSITIVITY!$I17)*(SENSITIVITY!M$88*(1-SENSITIVITY!$J$90)) -> 1350.7526 | N17: =('MODEL&SCHEDULE'!N$17-SENSITIVITY!M$85*SENSITIVITY!N$87+SENSITIVITY!M$85*SENSITIVITY!$I17)*(SENSITIVITY!N$88*(1-SENSITIVITY!$J$90)) -> 1484.485 | Q17: 0.03 | R17: 932.96949 | S17: 959.62577 | T17: 986.28204 | U17: 1011.8726 | V17: 1012.9383 | W17: 1039.5946 | X17: 1066.2509
I18: 0.09 | J18: =('MODEL&SCHEDULE'!J$17-SENSITIVITY!I$85*SENSITIVITY!J$87+SENSITIVITY!I$85*SENSITIVITY!$I18)*(SENSITIVITY!J$88*(1-SENSITIVITY!$J$90)) -> 1050.1567 | K18: =('MODEL&SCHEDULE'!K$17-SENSITIVITY!J$85*SENSITIVITY!K$87+SENSITIVITY!J$85*SENSITIVITY!$I18)*(SENSITIVITY!K$88*(1-SENSITIVITY!$J$90)) -> 1128.15 | L18: =('MODEL&SCHEDULE'!L$17-SENSITIVITY!K$85*SENSITIVITY!L$87+SENSITIVITY!K$85*SENSITIVITY!$I18)*(SENSITIVITY!L$88*(1-SENSITIVITY!$J$90)) -> 1225.0141 | M18: =('MODEL&SCHEDULE'!M$17-SENSITIVITY!L$85*SENSITIVITY!M$87+SENSITIVITY!L$85*SENSITIVITY!$I18)*(SENSITIVITY!M$88*(1-SENSITIVITY!$J$90)) -> 1355.7071 | N18: =('MODEL&SCHEDULE'!N$17-SENSITIVITY!M$85*SENSITIVITY!N$87+SENSITIVITY!M$85*SENSITIVITY!$I18)*(SENSITIVITY!N$88*(1-SENSITIVITY!$J$90)) -> 1490.0362 | Q18: 0.04 | R18: 942.02745 | S18: 968.94252 | T18: 995.85759 | U18: 1021.6966 | V18: 1022.7727 | W18: 1049.6877 | X18: 1076.6028
I19: 0.1 | J19: =('MODEL&SCHEDULE'!J$17-SENSITIVITY!I$85*SENSITIVITY!J$87+SENSITIVITY!I$85*SENSITIVITY!$I19)*(SENSITIVITY!J$88*(1-SENSITIVITY!$J$90)) -> 1053.8389 | K19: =('MODEL&SCHEDULE'!K$17-SENSITIVITY!J$85*SENSITIVITY!K$87+SENSITIVITY!J$85*SENSITIVITY!$I19)*(SENSITIVITY!K$88*(1-SENSITIVITY!$J$90)) -> 1132.0174 | L19: =('MODEL&SCHEDULE'!L$17-SENSITIVITY!K$85*SENSITIVITY!L$87+SENSITIVITY!K$85*SENSITIVITY!$I19)*(SENSITIVITY!L$88*(1-SENSITIVITY!$J$90)) -> 1229.2692 | M19: =('MODEL&SCHEDULE'!M$17-SENSITIVITY!L$85*SENSITIVITY!M$87+SENSITIVITY!L$85*SENSITIVITY!$I19)*(SENSITIVITY!M$88*(1-SENSITIVITY!$J$90)) -> 1360.6616 | N19: =('MODEL&SCHEDULE'!N$17-SENSITIVITY!M$85*SENSITIVITY!N$87+SENSITIVITY!M$85*SENSITIVITY!$I19)*(SENSITIVITY!N$88*(1-SENSITIVITY!$J$90)) -> 1495.5873 | Q19: 0.05 | R19: 951.08541 | S19: 978.25928 | T19: 1005.4331 | U19: 1031.5206 | V19: 1032.607 | W19: 1059.7809 | X19: 1086.9548
I20: 0.11 | J20: =('MODEL&SCHEDULE'!J$17-SENSITIVITY!I$85*SENSITIVITY!J$87+SENSITIVITY!I$85*SENSITIVITY!$I20)*(SENSITIVITY!J$88*(1-SENSITIVITY!$J$90)) -> 1057.5211 | K20: =('MODEL&SCHEDULE'!K$17-SENSITIVITY!J$85*SENSITIVITY!K$87+SENSITIVITY!J$85*SENSITIVITY!$I20)*(SENSITIVITY!K$88*(1-SENSITIVITY!$J$90)) -> 1135.8848 | L20: =('MODEL&SCHEDULE'!L$17-SENSITIVITY!K$85*SENSITIVITY!L$87+SENSITIVITY!K$85*SENSITIVITY!$I20)*(SENSITIVITY!L$88*(1-SENSITIVITY!$J$90)) -> 1233.5243 | M20: =('MODEL&SCHEDULE'!M$17-SENSITIVITY!L$85*SENSITIVITY!M$87+SENSITIVITY!L$85*SENSITIVITY!$I20)*(SENSITIVITY!M$88*(1-SENSITIVITY!$J$90)) -> 1365.6161 | N20: =('MODEL&SCHEDULE'!N$17-SENSITIVITY!M$85*SENSITIVITY!N$87+SENSITIVITY!M$85*SENSITIVITY!$I20)*(SENSITIVITY!N$88*(1-SENSITIVITY!$J$90)) -> 1501.1384 | Q20: 0.06 | R20: 960.14336 | S20: 987.57603 | T20: 1015.0087 | U20: 1041.3446 | V20: 1042.4414 | W20: 1069.874 | X20: 1097.3067
I21: 0.12 | J21: =('MODEL&SCHEDULE'!J$17-SENSITIVITY!I$85*SENSITIVITY!J$87+SENSITIVITY!I$85*SENSITIVITY!$I21)*(SENSITIVITY!J$88*(1-SENSITIVITY!$J$90)) -> 1061.2033 | K21: =('MODEL&SCHEDULE'!K$17-SENSITIVITY!J$85*SENSITIVITY!K$87+SENSITIVITY!J$85*SENSITIVITY!$I21)*(SENSITIVITY!K$88*(1-SENSITIVITY!$J$90)) -> 1139.7522 | L21: =('MODEL&SCHEDULE'!L$17-SENSITIVITY!K$85*SENSITIVITY!L$87+SENSITIVITY!K$85*SENSITIVITY!$I21)*(SENSITIVITY!L$88*(1-SENSITIVITY!$J$90)) -> 1237.7793 | M21: =('MODEL&SCHEDULE'!M$17-SENSITIVITY!L$85*SENSITIVITY!M$87+SENSITIVITY!L$85*SENSITIVITY!$I21)*(SENSITIVITY!M$88*(1-SENSITIVITY!$J$90)) -> 1370.5706 | N21: =('MODEL&SCHEDULE'!N$17-SENSITIVITY!M$85*SENSITIVITY!N$87+SENSITIVITY!M$85*SENSITIVITY!$I21)*(SENSITIVITY!N$88*(1-SENSITIVITY!$J$90)) -> 1506.6896 | Q21: 0.07 | R21: 969.20132 | S21: 996.89279 | T21: 1024.5843 | U21: 1051.1686 | V21: 1052.2757 | W21: 1079.9672 | X21: 1107.6587
I22: 0.13 | J22: =('MODEL&SCHEDULE'!J$17-SENSITIVITY!I$85*SENSITIVITY!J$87+SENSITIVITY!I$85*SENSITIVITY!$I22)*(SENSITIVITY!J$88*(1-SENSITIVITY!$J$90)) -> 1064.8855 | K22: =('MODEL&SCHEDULE'!K$17-SENSITIVITY!J$85*SENSITIVITY!K$87+SENSITIVITY!J$85*SENSITIVITY!$I22)*(SENSITIVITY!K$88*(1-SENSITIVITY!$J$90)) -> 1143.6196 | L22: =('MODEL&SCHEDULE'!L$17-SENSITIVITY!K$85*SENSITIVITY!L$87+SENSITIVITY!K$85*SENSITIVITY!$I22)*(SENSITIVITY!L$88*(1-SENSITIVITY!$J$90)) -> 1242.0344 | M22: =('MODEL&SCHEDULE'!M$17-SENSITIVITY!L$85*SENSITIVITY!M$87+SENSITIVITY!L$85*SENSITIVITY!$I22)*(SENSITIVITY!M$88*(1-SENSITIVITY!$J$90)) -> 1375.5251 | N22: =('MODEL&SCHEDULE'!N$17-SENSITIVITY!M$85*SENSITIVITY!N$87+SENSITIVITY!M$85*SENSITIVITY!$I22)*(SENSITIVITY!N$88*(1-SENSITIVITY!$J$90)) -> 1512.2407 | Q22: 0.08 | R22: 978.25927 | S22: 1006.2095 | T22: 1034.1598 | U22: 1060.9927 | V22: 1062.1101 | W22: 1090.0603 | X22: 1118.0106
I23: 0.14 | J23: =('MODEL&SCHEDULE'!J$17-SENSITIVITY!I$85*SENSITIVITY!J$87+SENSITIVITY!I$85*SENSITIVITY!$I23)*(SENSITIVITY!J$88*(1-SENSITIVITY!$J$90)) -> 1068.5677 | K23: =('MODEL&SCHEDULE'!K$17-SENSITIVITY!J$85*SENSITIVITY!K$87+SENSITIVITY!J$85*SENSITIVITY!$I23)*(SENSITIVITY!K$88*(1-SENSITIVITY!$J$90)) -> 1147.487 | L23: =('MODEL&SCHEDULE'!L$17-SENSITIVITY!K$85*SENSITIVITY!L$87+SENSITIVITY!K$85*SENSITIVITY!$I23)*(SENSITIVITY!L$88*(1-SENSITIVITY!$J$90)) -> 1246.2895 | M23: =('MODEL&SCHEDULE'!M$17-SENSITIVITY!L$85*SENSITIVITY!M$87+SENSITIVITY!L$85*SENSITIVITY!$I23)*(SENSITIVITY!M$88*(1-SENSITIVITY!$J$90)) -> 1380.4796 | N23: =('MODEL&SCHEDULE'!N$17-SENSITIVITY!M$85*SENSITIVITY!N$87+SENSITIVITY!M$85*SENSITIVITY!$I23)*(SENSITIVITY!N$88*(1-SENSITIVITY!$J$90)) -> 1517.7918 | Q23: 0.09 | R23: 987.31723 | S23: 1015.5263 | T23: 1043.7354 | U23: 1070.8167 | V23: 1071.9444 | W23: 1100.1535 | X23: 1128.3626
... I26: 0.17 | J26: =('MODEL&SCHEDULE'!J$17-SENSITIVITY!I$85*SENSITIVITY!J$87+SENSITIVITY!I$85*SENSITIVITY!$I26)*(SENSITIVITY!J$88*(1-SENSITIVITY!$J$90)) -> 1079.6144 | K26: =('MODEL&SCHEDULE'!K$17-SENSITIVITY!J$85*SENSITIVITY!K$87+SENSITIVITY!J$85*SENSITIVITY!$I26)*(SENSITIVITY!K$88*(1-SENSITIVITY!$J$90)) -> 1159.0891 | L26: =('MODEL&SCHEDULE'!L$17-SENSITIVITY!K$85*SENSITIVITY!L$87+SENSITIVITY!K$85*SENSITIVITY!$I26)*(SENSITIVITY!L$88*(1-SENSITIVITY!$J$90)) -> 1259.0547 | M26: =('MODEL&SCHEDULE'!M$17-SENSITIVITY!L$85*SENSITIVITY!M$87+SENSITIVITY!L$85*SENSITIVITY!$I26)*(SENSITIVITY!M$88*(1-SENSITIVITY!$J$90)) -> 1395.343 | N26: =('MODEL&SCHEDULE'!N$17-SENSITIVITY!M$85*SENSITIVITY!N$87+SENSITIVITY!M$85*SENSITIVITY!$I26)*(SENSITIVITY!N$88*(1-SENSITIVITY!$J$90)) -> 1534.4452 | Q26: 0.12 | R26: 1014.4911 | S26: 1043.4766 | T26: 1072.462 | U26: 1100.2887 | V26: 1101.4475 | W26: 1130.4329 | X26: 1159.4184
B52: Tornado Chart Data + Chart
C53: Driver | D53: High Case | E53: Model Cases | F53: Low case | G53: Downside | H53: Upside | I53: range
C54: =C97 -> Revenue Growth | D54: 0.08 | E54: =J97 -> 0.054251228 | F54: -0.04
C55: =C88 -> EBIT margin | D55: 0.21066821 | E55: =J88 -> 0.18975078 | F55: 0.17066821
C56: =C89 -> Cost of sales as a % of revenue | D56: 0.54 | E56: =J89 -> 0.5608681 | F56: 0.58
C57: =C90 -> Reported ETR | D57: 0.24 | E57: =J90 -> 0.25 | F57: 0.26
C58: EBIT margin cal using Cost of sales | D58: =(1-D$56-$J$99) -> 0.21061888 | E58: =(1-E$56-$J$99) -> 0.18975078 | F58: =(1-F$56-$J$99) -> 0.17061888
C59: NOPAT | E59: =$I$96*(1+E54)*($E$55*(1-E57)) -> 1035.4279
C60: Revenue Growth | D60: =$I$96*(1+D$54)*($E$55*(1-$E$57)) -> 1060.7169 | F60: =$I$96*(1+F$54)*($E$55*(1-$E$57)) -> 942.85946 | G60: =F60-$E$59 -> -92.568398 | H60: =D60-$E$59 -> 25.289035 | I60: =H60-G60 -> 117.85743
C61: =C55 -> EBIT margin | D61: =$I$96*(1+$E$54)*(D$55*(1-$E$57)) -> 1149.5697 | F61: =$I$96*(1+$E$54)*(F$55*(1-$E$57)) -> 931.29853 | G61: =F61-$E$59 -> -104.12933 | H61: =D61-$E$59 -> 114.14179 | I61: =H61-G61 -> 218.27112
C62: =C56 -> Cost of sales as a % of revenue | D62: =$I$96*(1+$E$54)*(D$58*(1-$E$57)) -> 1149.3005 | F62: =$I$96*(1+$E$54)*(F$58*(1-$E$57)) -> 931.02935 | G62: =F62-$E$59 -> -104.39852 | H62: =D62-$E$59 -> 113.8726 | I62: =H62-G62 -> 218.27112
C63: =C57 -> Reported ETR | D63: =$I$96*(1+$E$54)*($E$55*(1-D$57)) -> 1049.2336 | F63: =$I$96*(1+$E$54)*($E$55*(1-F$57)) -> 1021.6222 | G63: =F63-$E$59 -> -13.805705 | H63: =D63-$E$59 -> 13.805705 | I63: =H63-G63 -> 27.61141
B66: Sorting
C67: =C61 -> EBIT margin | D67: =D61 -> 1149.5697 | F67: =F61 -> 931.29853 | G67: =G61 -> -104.12933 | H67: =H61 -> 114.14179 | I67: =I61 -> 218.27112
C68: =C60 -> Revenue Growth | D68: =D60 -> 1060.7169 | F68: =F60 -> 942.85946 | G68: =G60 -> -92.568398 | H68: =H60 -> 25.289035 | I68: =I60 -> 117.85743
C69: =C63 -> Reported ETR | D69: =D63 -> 1049.2336 | F69: =F63 -> 1021.6222 | G69: =G63 -> -13.805705 | H69: =H63 -> 13.805705 | I69: =I63 -> 27.61141
B72: Chart Input Table
...

Sheet DCF
C8: WACC from First Principles:

Sheet LBO ANALYSIS

Sheet REGRESSION

Sheet COMPS
C6: peers
C7: Sainsbury | E7: 0.156 | F7: 0.155 | G7: 0.152 | H7: 0.156 | I7: 0.158
C8: asda | E8: 0.144 | F8: 0.141 | G8: 0.138 | H8: 0.133 | I8: 0.123
C9: aldi | E9: 0.08 | F9: 0.086 | G9: 0.1 | H9: 0.1 | I9: 0.102
C10: morrisons | E10: 0.102 | F10: 0.097 | G10: 0.089 | H10: 0.087 | I10: 0.085
C11: lidl | E11: 0.053 | F11: 0.058 | G11: 0.067 | H11: 0.07 | I11: 0.073
C12: co-op | E12: 0.062 | F12: 0.059 | G12: 0.057 | H12: 0.054 | I12: 0.053
C13: waitrose | E13: 0.052 | F13: 0.049 | G13: 0.048 | H13: 0.047 | I13: 0.047
C14: iceland | E14: 0.025 | F14: 0.024 | G14: 0.024 | H14: 0.024 | I14: 0.023
C15: ocado | E15: 0.017 | F15: 0.017 | G15: 0.017 | H15: 0.018 | I15: 0.019

Sheet MONTE CARLO

Sheet CHECKS

Sheet DASHBOARD

Sheet SOTP

Sheet ACCOUNTING
B6: IFRS 16
B13: IAS 19
B20: IFRS 2
B26: INTANGIBLES

Sheet SOURCE
A4: 46177 | B4: =ASSUMPTIONS!C299 -> Risk- Free Rate % | C4: 46022 | D4: End year level of yield from British Government Stock, 10 year Nominal Par Yield IUAMNPY | E4: https://www.bankofengland.co.uk/boeapps/database/fromshowcolumns.asp?Travel=NIxIRxSUx&FromSeries=1&ToSeries=50&DAT=RNG&FD=1&FM=Jan&FY=2015&TD=31&TM=Dec&TY=2026&FNY=&CSVF=TT&VPD=Y&NewRevSince=Y&RFD=3&RFM=Jun&RFY=2007&html.x=222&html.y=43&C=DUS&C=DVI&Filter=Y&VUD=B | G4: https://www.bankofengland.co.uk/boeapps/database/fromshowcolumns.asp?Travel=NIxIRxSUx&FromSeries=1&ToSeries=50&DAT=RNG&FD=1&FM=Jan&FY=2015&TD=31&TM=Dec&TY=2026&FNY=&CSVF=TT&VPD=Y&NewRevSince=Y&RFD=3&RFM=Jun&RFY=2007&html.x=222&html.y=43&C=DUS&C=DVI&Filter=Y&VUD=B#
A5: =A4 -> 46177 | B5: =ASSUMPTIONS!C307 -> unlevered beta corrected for cash | C5: 46027 | E5: https://pages.stern.nyu.edu/~adamodar/New_Home_Page/datacurrent.html#discrate | G5: https://pages.stern.nyu.edu/~adamodar/pc/datasets/betaEurope.xls
A6: =A5 -> 46177 | B6: cost of equity (Europe) | C6: 0.091151863 | D6: retail(grocery and food) | E6: =E5 -> https://pages.stern.nyu.edu/~adamodar/New_Home_Page/datacurrent.html#discrate | G6: https://pages.stern.nyu.edu/~adamodar/pc/datasets/waccEurope.xls
A7: =A6 -> 46177 | B7: cost of capital(europe) | C7: 0.073766936 | D7: =D6 -> retail(grocery and food) | E7: =E6 -> https://pages.stern.nyu.edu/~adamodar/New_Home_Page/datacurrent.html#discrate | G7: https://pages.stern.nyu.edu/~adamodar/pc/datasets/waccEurope.xls
A8: =A7 -> 46177 | B8: =ASSUMPTIONS!C300 -> Equity Risk Premium % | C8: 46023 | D8: Risk Premiums for Other Markets | E8: =E7 -> https://pages.stern.nyu.edu/~adamodar/New_Home_Page/datacurrent.html#discrate | G8: https://pages.stern.nyu.edu/~adamodar/pc/datasets/ctryprem.xlsx
A9: =A8 -> 46177 | B9: =ASSUMPTIONS!#REF! -> #REF! | C9: 12weeks ending feb | D9: market share | E9: https://www.kantar.com/uki/campaigns/grocery-market-share
B10: =ASSUMPTIONS!#REF! -> #REF! | C10: February figure(Vol) | D10: Retail Sales Index time series | E10: https://www.ons.gov.uk/businessindustryandtrade/retailindustry/datasets/retailsales | G10: https://www.ons.gov.uk/file?uri=/businessindustryandtrade/retailindustry/datasets/retailsales/current/drsi.xlsx
B11: =ASSUMPTIONS!C32 -> UK CPI Inflation | C11: february | D11: %change over 12months | E11: https://www.ons.gov.uk/economy/inflationandpriceindices/datasets/consumerpriceinflation/current
A14: 46197 | B14: SONIA | C14: Daily rate | D14: Bank of England | E14: https://www.bankofengland.co.uk/boeapps/database/fromshowcolumns.asp?Travel=NIxSUx&FromSeries=1&ToSeries=50&DAT=RNG&FD=1&FM=Jan&FY=2014&TD=6&TM=Dec&TY=2040&FNY=&CSVF=TT&html.x=180&html.y=34&C=5JK&Filter=N

Sheet rough sheet
C2: PRACTICAL MODELLING DECISION: for your BASE CASE, assume the FULL £500m goes to buybacks (simplest, and the PRIMARY stated intention). Build a SCENARIO/SENSITIVITY toggle for "if share price exceeds £131, X% diverts to special dividend instead" if you want to show this risk — but it's not required for your base case.
W3: to to eliminate
W5: 2021
U7: ═══════════════════════════════════════════════════════
U8: SEGMENT REVENUE BUILD (feeds into the IS, shown as
U9: supporting schedule or top section)
U10: ═══════════════════════════════════════════════════════ | W10: 3284.1
U11: Online UK | W11: 250.3
U12: Online International | W12: =W10+W11 -> 3534.4
U13: NEXT Online subtotal | W13: 2231.7
U14: Next Retail | W14: 54.8
U15: Next Finance / credit interest | W15: =W12-W13-W14 -> 1247.9
U16: Total Platform | W16: 555.8
U17: Other business activities | W17: 246.8
U18: ───────────────────────────────────────────────────── | W18: -1.3
U19: TOTAL STATUTORY REVENUE [Check: 0] | W19: =W15-W16-W17+W18 -> 444
W20: 0.5
U21: YoY revenue growth %
W23: =SUM(W19:W22) -> 444.5
U24: ═══════════════════════════════════════════════════════
U25: COST OF SALES / GROSS PROFIT | W25: 0.6
U26: ═══════════════════════════════════════════════════════ | W26: -102.7
U27: Cost of sales | W27: =SUM(W23:W26) -> 342.4
U28: Expected credit loss (ECL) on Finance receivables | W28: -55.7
U29: ───────────────────────────────────────────────────── | W29: =SUM(W27:W28) -> 286.7
U30: GROSS PROFIT
U31: Gross margin %
U34: ═══════════════════════════════════════════════════════
U35: OPERATING EXPENSES | W35: =SUM(W33:W34) -> 0
U36: ═══════════════════════════════════════════════════════
U37: Distribution costs | W37: 223.3p
U38: Administrative expenses | W38: 221.9p
U39: (before exceptional items / adjusting items split out)
U40: ─────────────────────────────────────────────────────
U41: TRADING PROFIT
U44: ═══════════════════════════════════════════════════════
U45: BELOW TRADING PROFIT, ABOVE EBIT
U46: ═══════════════════════════════════════════════════════
U47: Share of profit from associates and joint ventures
U48: Impairment of associates/JV investments | W48: 444.5
...
